Workbook

Sheet BD Asesor
V1: =DAY(Listas!B2) -> 19 | X1: =MONTH(Listas!B2) -> 5
B3: Base de Datos asesor
D5: 2 meses antes | I5: Día de su cumpleaños
D6: 10 dias antes | I6: 5 dias antes
A7: Cliente | B7: Sexo | C7: Estado | D7: Emisión | E7: Número de póliza | F7: Prima anual | G7: Tipo de Moneda | H7: Forma de pago | I7: Cumpleaños | J7: Buen referenciador | K7: Modo de cobro | L7: Tipo de plan | M7: Nombre del plan | N7: Correo electrónico | O7: Teléfono | P7: Asesor | Q7: Mes | R7: Año | S7: DiaEm | T7: Diferencia de dia | U7: MesEm | V7: DiaCu | W7: Diferencia Cu | X7: MesCu | Y7: MesNum | Z7: Años | AA7: Bloques edad
A8: ABRAHAM GALICIA MANCERA | B8: H | C8: Activo | D8: 44238 | E8: GM0000512930 | F8: =1413.91*12 -> 16966.92 | G8: MXN | H8: Mensual | I8: 15-sep | J8: Sí | K8: TD | L8: Gastos Médicos | M8: Integro | N8: abraham.mancera92@hotmail.com | O8: 3322725657 | P8: =IF(A8="","", "DARINKA UREÑA CASILLAS") -> DARINKA UREÑA CASILLAS | Q8: =IF(D8="","",VLOOKUP(MONTH(D8),Listas!$C$2:$D$14,2,0)) -> Febrero | R8: =IF(D8="","",YEAR(D8)) -> 2021 | S8: =IF(D8="","",(DAY(D8))) -> 11 | T8: =IF(D8="","",S8-$W$1) -> 11 | U8: =IF(D8="","",(MONTH(D8))) -> 2 | V8: =IF(I8="","",(DAY(I8))) -> 15 | W8: =IF(I8="","",V8-$W$1) -> 15 | X8: =IF(I8="","",(MONTH(I8))) -> 9 | Y8: =IF(D8="","",(MONTH(D8))) -> 2 | Z8: =IFERROR(IF(I8="","", DATEDIF(I8, TODAY(), "Y")),0) -> 0 | AA8: =IF(Z8="","", IFS(Z8 >= 61, "61+ años", Z8 >= 51, "51-60 años", Z8 >= 40, "40-50 años", Z8 >= 20, "20-39 años", TRUE, "-20 años")) -> -20 años
A9: ABRAHAM GALICIA MANCERA | B9: H | C9: Activo | D9: 44247 | E9: VI0002585905 | F9: =727.3*12*7.65 -> 66766.14 | G9: UDIS | H9: Mensual | I9: 15-sep | J9: Sí | K9: TD | L9: Vida | M9: Orvi | N9: abraham.mancera92@hotmail.com | O9: 3322725657 | P9: =IF(A9="","", "DARINKA UREÑA CASILLAS") -> DARINKA UREÑA CASILLAS | Q9: =IF(D9="","",VLOOKUP(MONTH(D9),Listas!$C$2:$D$14,2,0)) -> Febrero | R9: =IF(D9="","",YEAR(D9)) -> 2021 | S9: =IF(D9="","",(DAY(D9))) -> 20 | T9: =IF(D9="","",S9-$W$1) -> 20 | U9: =IF(D9="","",(MONTH(D9))) -> 2 | V9: =IF(I9="","",(DAY(I9))) -> 15 | W9: =IF(I9="","",V9-$W$1) -> 15 | X9: =IF(I9="","",(MONTH(I9))) -> 9 | Y9: =IF(D9="","",(MONTH(D9))) -> 2 | Z9: =IFERROR(IF(I9="","", DATEDIF(I9, TODAY(), "Y")),0) -> 0 | AA9: =IF(Z9="","", IFS(Z9 >= 61, "61+ años", Z9 >= 51, "51-60 años", Z9 >= 40, "40-50 años", Z9 >= 20, "20-39 años", TRUE, "-20 años")) -> -20 años
A10: ADRIAN ALEJANDRO RAMIREZ MORALES | B10: H | C10: Activo | D10: 44581 | E10: GM0000551209 | F10: =11035.51*2 -> 22071.02 | G10: MXN | H10: Semestral | I10: 44707 | K10: TD | L10: Gastos Médicos | M10: Practico | N10: adriangtsramirez261144@gmail.com | O10: 3335785031 | P10: =IF(A10="","", "DARINKA UREÑA CASILLAS") -> DARINKA UREÑA CASILLAS | Q10: =IF(D10="","",VLOOKUP(MONTH(D10),Listas!$C$2:$D$14,2,0)) -> Enero | R10: =IF(D10="","",YEAR(D10)) -> 2022 | S10: =IF(D10="","",(DAY(D10))) -> 20 | T10: =IF(D10="","",S10-$W$1) -> 20 | U10: =IF(D10="","",(MONTH(D10))) -> 1 | V10: =IF(I10="","",(DAY(I10))) -> 26 | W10: =IF(I10="","",V10-$W$1) -> 26 | X10: =IF(I10="","",(MONTH(I10))) -> 5 | Y10: =IF(D10="","",(MONTH(D10))) -> 1 | Z10: =IFERROR(IF(I10="","", DATEDIF(I10, TODAY(), "Y")),0) -> 3 | AA10: =IF(Z10="","", IFS(Z10 >= 61, "61+ años", Z10 >= 51, "51-60 años", Z10 >= 40, "40-50 años", Z10 >= 20, "20-39 años", TRUE, "-20 años")) -> -20 años
A11: ADRIAN ALEJANDRO RAMIREZ MORALES | B11: H | C11: Activo | D11: 44576 | E11: VI0002645864 | F11: =572.77*12*7.65 -> 52580.286 | G11: UDIS | H11: Mensual | I11: 44707 | K11: TC | L11: Vida | M11: Orvi | N11: adriangtsramirez261144@gmail.com | O11: 3335785031 | P11: =IF(A11="","", "DARINKA UREÑA CASILLAS") -> DARINKA UREÑA CASILLAS | Q11: =IF(D11="","",VLOOKUP(MONTH(D11),Listas!$C$2:$D$14,2,0)) -> Enero | R11: =IF(D11="","",YEAR(D11)) -> 2022 | S11: =IF(D11="","",(DAY(D11))) -> 15 | T11: =IF(D11="","",S11-$W$1) -> 15 | U11: =IF(D11="","",(MONTH(D11))) -> 1 | V11: =IF(I11="","",(DAY(I11))) -> 26 | W11: =IF(I11="","",V11-$W$1) -> 26 | X11: =IF(I11="","",(MONTH(I11))) -> 5 | Y11: =IF(D11="","",(MONTH(D11))) -> 1 | Z11: =IFERROR(IF(I11="","", DATEDIF(I11, TODAY(), "Y")),0) -> 3 | AA11: =IF(Z11="","", IFS(Z11 >= 61, "61+ años", Z11 >= 51, "51-60 años", Z11 >= 40, "40-50 años", Z11 >= 20, "20-39 años", TRUE, "-20 años")) -> -20 años
A12: AIDA GRACIELA FLORES BARBA | B12: M | C12: Activo | D12: 44168 | E12: VI0002570983 | F12: =3637.65*7.65 -> 27828.022 | G12: UDIS | H12: Anual | I12: 44704 | K12: TC | L12: Vida | M12: Orvi | N12: ajj_07@hotmail.com | O12: 3314550115 | P12: =IF(A12="","", "DARINKA UREÑA CASILLAS") -> DARINKA UREÑA CASILLAS | Q12: =IF(D12="","",VLOOKUP(MONTH(D12),Listas!$C$2:$D$14,2,0)) -> Diciembre | R12: =IF(D12="","",YEAR(D12)) -> 2020 | S12: =IF(D12="","",(DAY(D12))) -> 3 | T12: =IF(D12="","",S12-$W$1) -> 3 | U12: =IF(D12="","",(MONTH(D12))) -> 12 | V12: =IF(I12="","",(DAY(I12))) -> 23 | W12: =IF(I12="","",V12-$W$1) -> 23 | X12: =IF(I12="","",(MONTH(I12))) -> 5 | Y12: =IF(D12="","",(MONTH(D12))) -> 12 | Z12: =IFERROR(IF(I12="","", DATEDIF(I12, TODAY(), "Y")),0) -> 3 | AA12: =IF(Z12="","", IFS(Z12 >= 61, "61+ años", Z12 >= 51, "51-60 años", Z12 >= 40, "40-50 años", Z12 >= 20, "20-39 años", TRUE, "-20 años")) -> -20 años
A13: ALEJANDRA DEL CARMEN UREÑA CASILLAS | B13: M | C13: Activo | D13: 44008 | E13: GM0000478411 | F13: 10660.33 | G13: MXN | H13: Anual | I13: 45206 | K13: TC | L13: Gastos Médicos | M13: Integro | N13: ale_u_casillas@hotmail.com | O13: 3322590323 | P13: =IF(A13="","", "DARINKA UREÑA CASILLAS") -> DARINKA UREÑA CASILLAS | Q13: =IF(D13="","",VLOOKUP(MONTH(D13),Listas!$C$2:$D$14,2,0)) -> Junio | R13: =IF(D13="","",YEAR(D13)) -> 2020 | S13: =IF(D13="","",(DAY(D13))) -> 26 | T13: =IF(D13="","",S13-$W$1) -> 26 | U13: =IF(D13="","",(MONTH(D13))) -> 6 | V13: =IF(I13="","",(DAY(I13))) -> 7 | W13: =IF(I13="","",V13-$W$1) -> 7 | X13: =IF(I13="","",(MONTH(I13))) -> 10 | Y13: =IF(D13="","",(MONTH(D13))) -> 6 | Z13: =IFERROR(IF(I13="","", DATEDIF(I13, TODAY(), "Y")),0) -> 2 | AA13: =IF(Z13="","", IFS(Z13 >= 61, "61+ años", Z13 >= 51, "51-60 años", Z13 >= 40, "40-50 años", Z13 >= 20, "20-39 años", TRUE, "-20 años")) -> -20 años
A14: ALEJANDRA DEL CARMEN UREÑA CASILLAS | B14: M | C14: Activo | D14: 44844 | E14: GM0000579437 | F14: =6745*2 -> 13490 | G14: MXN | H14: Semestral | I14: 45170 | K14: TC | L14: Gastos Médicos | M14: Practico | N14: ale_u_casillas@hotmail.com | O14: 3322590323 | P14: =IF(A14="","", "DARINKA UREÑA CASILLAS") -> DARINKA UREÑA CASILLAS | Q14: =IF(D14="","",VLOOKUP(MONTH(D14),Listas!$C$2:$D$14,2,0)) -> Octubre | R14: =IF(D14="","",YEAR(D14)) -> 2022 | S14: =IF(D14="","",(DAY(D14))) -> 10 | T14: =IF(D14="","",S14-$W$1) -> 10 | U14: =IF(D14="","",(MONTH(D14))) -> 10 | V14: =IF(I14="","",(DAY(I14))) -> 1 | W14: =IF(I14="","",V14-$W$1) -> 1 | X14: =IF(I14="","",(MONTH(I14))) -> 9 | Y14: =IF(D14="","",(MONTH(D14))) -> 10 | Z14: =IFERROR(IF(I14="","", DATEDIF(I14, TODAY(), "Y")),0) -> 2 | AA14: =IF(Z14="","", IFS(Z14 >= 61, "61+ años", Z14 >= 51, "51-60 años", Z14 >= 40, "40-50 años", Z14 >= 20, "20-39 años", TRUE, "-20 años")) -> -20 años
A15: ALEJANDRA DEL CARMEN UREÑA CASILLAS | B15: M | C15: Activo | D15: 43893 | E15: VI0002521501 | F15: =5302.35*7.65 -> 40562.978 | G15: UDIS | H15: Anual | I15: 44805 | K15: TD | L15: Vida | M15: Orvi | N15: ale_u_casillas@hotmail.com | O15: 3322590323 | P15: =IF(A15="","", "DARINKA UREÑA CASILLAS") -> DARINKA UREÑA CASILLAS | Q15: =IF(D15="","",VLOOKUP(MONTH(D15),Listas!$C$2:$D$14,2,0)) -> Marzo | R15: =IF(D15="","",YEAR(D15)) -> 2020 | S15: =IF(D15="","",(DAY(D15))) -> 3 | T15: =IF(D15="","",S15-$W$1) -> 3 | U15: =IF(D15="","",(MONTH(D15))) -> 3 | V15: =IF(I15="","",(DAY(I15))) -> 1 | W15: =IF(I15="","",V15-$W$1) -> 1 | X15: =IF(I15="","",(MONTH(I15))) -> 9 | Y15: =IF(D15="","",(MONTH(D15))) -> 3 | Z15: =IFERROR(IF(I15="","", DATEDIF(I15, TODAY(), "Y")),0) -> 3 | AA15: =IF(Z15="","", IFS(Z15 >= 61, "61+ años", Z15 >= 51, "51-60 años", Z15 >= 40, "40-50 años", Z15 >= 20, "20-39 años", TRUE, "-20 años")) -> -20 años
A16: ALEJANDRO ARTURO LOMELI OROZCO | B16: H | C16: Activo | D16: 44753 | E16: VI0002678022 | F16: =1674.59*2*7.65 -> 25621.227 | G16: UDIS | H16: Semestral | I16: 45024 | K16: TD | L16: Vida | M16: Orvi | N16: aa.lomeli8@gmail.com | O16: 3322278793 | P16: =IF(A16="","", "DARINKA UREÑA CASILLAS") -> DARINKA UREÑA CASILLAS | Q16: =IF(D16="","",VLOOKUP(MONTH(D16),Listas!$C$2:$D$14,2,0)) -> Julio | R16: =IF(D16="","",YEAR(D16)) -> 2022 | S16: =IF(D16="","",(DAY(D16))) -> 11 | T16: =IF(D16="","",S16-$W$1) -> 11 | U16: =IF(D16="","",(MONTH(D16))) -> 7 | V16: =IF(I16="","",(DAY(I16))) -> 8 | W16: =IF(I16="","",V16-$W$1) -> 8 | X16: =IF(I16="","",(MONTH(I16))) -> 4 | Y16: =IF(D16="","",(MONTH(D16))) -> 7 | Z16: =IFERROR(IF(I16="","", DATEDIF(I16, TODAY(), "Y")),0) -> 3 | AA16: =IF(Z16="","", IFS(Z16 >= 61, "61+ años", Z16 >= 51, "51-60 años", Z16 >= 40, "40-50 años", Z16 >= 20, "20-39 años", TRUE, "-20 años")) -> -20 años
A17: ALEJANDRO MORENO TRUJILLO | B17: H | C17: Activo | D17: 44581 | E17: GM0000551319 | F17: 25192.01 | G17: MXN | H17: Anual | I17: 44656 | K17: TC | L17: Gastos Médicos | M17: Practico | N17: alejandromorenotrujillo1@gmail.com | O17: 3324945143 | P17: =IF(A17="","", "DARINKA UREÑA CASILLAS") -> DARINKA UREÑA CASILLAS | Q17: =IF(D17="","",VLOOKUP(MONTH(D17),Listas!$C$2:$D$14,2,0)) -> Enero | R17: =IF(D17="","",YEAR(D17)) -> 2022 | S17: =IF(D17="","",(DAY(D17))) -> 20 | T17: =IF(D17="","",S17-$W$1) -> 20 | U17: =IF(D17="","",(MONTH(D17))) -> 1 | V17: =IF(I17="","",(DAY(I17))) -> 5 | W17: =IF(I17="","",V17-$W$1) -> 5 | X17: =IF(I17="","",(MONTH(I17))) -> 4 | Y17: =IF(D17="","",(MONTH(D17))) -> 1 | Z17: =IFERROR(IF(I17="","", DATEDIF(I17, TODAY(), "Y")),0) -> 4 | AA17: =IF(Z17="","", IFS(Z17 >= 61, "61+ años", Z17 >= 51, "51-60 años", Z17 >= 40, "40-50 años", Z17 >= 20, "20-39 años", TRUE, "-20 años")) -> -20 años
A18: ALEJANDRO MORENO TRUJILLO | B18: H | C18: Activo | D18: 44603 | E18: VI0002650072 | F18: =5531.93*2*7.65 -> 84638.529 | G18: UDIS | H18: Semestral | I18: 44656 | K18: TD | L18: Vida | M18: Orvi | N18: alejandromorenotrujillo1@gmail.com | O18: 3324945143 | P18: =IF(A18="","", "DARINKA UREÑA CASILLAS") -> DARINKA UREÑA CASILLAS | Q18: =IF(D18="","",VLOOKUP(MONTH(D18),Listas!$C$2:$D$14,2,0)) -> Febrero | R18: =IF(D18="","",YEAR(D18)) -> 2022 | S18: =IF(D18="","",(DAY(D18))) -> 11 | T18: =IF(D18="","",S18-$W$1) -> 11 | U18: =IF(D18="","",(MONTH(D18))) -> 2 | V18: =IF(I18="","",(DAY(I18))) -> 5 | W18: =IF(I18="","",V18-$W$1) -> 5 | X18: =IF(I18="","",(MONTH(I18))) -> 4 | Y18: =IF(D18="","",(MONTH(D18))) -> 2 | Z18: =IFERROR(IF(I18="","", DATEDIF(I18, TODAY(), "Y")),0) -> 4 | AA18: =IF(Z18="","", IFS(Z18 >= 61, "61+ años", Z18 >= 51, "51-60 años", Z18 >= 40, "40-50 años", Z18 >= 20, "20-39 años", TRUE, "-20 años")) -> -20 años
A19: ALEJANDRO SOTO ELIZALDE | B19: H | C19: Activo | D19: 44467 | E19: GM0000540142 | F19: 15641.78 | G19: MXN | H19: Semestral | I19: 44590 | K19: TD | L19: Gastos Médicos | M19: Integro | N19: soto.564@hotmail.com | O19: 3339561889 | P19: =IF(A19="","", "DARINKA UREÑA CASILLAS") -> DARINKA UREÑA CASILLAS | Q19: =IF(D19="","",VLOOKUP(MONTH(D19),Listas!$C$2:$D$14,2,0)) -> Septiembre | R19: =IF(D19="","",YEAR(D19)) -> 2021 | S19: =IF(D19="","",(DAY(D19))) -> 28 | T19: =IF(D19="","",S19-$W$1) -> 28 | U19: =IF(D19="","",(MONTH(D19))) -> 9 | V19: =IF(I19="","",(DAY(I19))) -> 29 | W19: =IF(I19="","",V19-$W$1) -> 29 | X19: =IF(I19="","",(MONTH(I19))) -> 1 | Y19: =IF(D19="","",(MONTH(D19))) -> 9 | Z19: =IFERROR(IF(I19="","", DATEDIF(I19, TODAY(), "Y")),0) -> 4 | AA19: =IF(Z19="","", IFS(Z19 >= 61, "61+ años", Z19 >= 51, "51-60 años", Z19 >= 40, "40-50 años", Z19 >= 20, "20-39 años", TRUE, "-20 años")) -> -20 años
A20: ALEJANDRO VAZQUEZ RODRIGUEZ | B20: H | C20: Activo | D20: 44042 | E20: VI0002546462 | F20: =324.24*12*7.65 -> 29765.232 | G20: UDIS | H20: Mensual | I20: 44769 | K20: TC | L20: Vida | M20: Orvi | N20: a.vazquez.rodriguez@outlook.com | O20: 3318332966 | P20: =IF(A20="","", "DARINKA UREÑA CASILLAS") -> DARINKA UREÑA CASILLAS | Q20: =IF(D20="","",VLOOKUP(MONTH(D20),Listas!$C$2:$D$14,2,0)) -> Julio | R20: =IF(D20="","",YEAR(D20)) -> 2020 | S20: =IF(D20="","",(DAY(D20))) -> 30 | T20: =IF(D20="","",S20-$W$1) -> 30 | U20: =IF(D20="","",(MONTH(D20))) -> 7 | V20: =IF(I20="","",(DAY(I20))) -> 27 | W20: =IF(I20="","",V20-$W$1) -> 27 | X20: =IF(I20="","",(MONTH(I20))) -> 7 | Y20: =IF(D20="","",(MONTH(D20))) -> 7 | Z20: =IFERROR(IF(I20="","", DATEDIF(I20, TODAY(), "Y")),0) -> 3 | AA20: =IF(Z20="","", IFS(Z20 >= 61, "61+ años", Z20 >= 51, "51-60 años", Z20 >= 40, "40-50 años", Z20 >= 20, "20-39 años", TRUE, "-20 años")) -> -20 años
A21: ALEXA GISELLE INFANTE JAIME | B21: M | C21: Activo | D21: 44125 | E21: GM0000496075 | F21: =1542.83*12 -> 18513.96 | G21: MXN | H21: Mensual | I21: 44634 | K21: TC | L21: Gastos Médicos | M21: Practico | N21: giselleinfante92@gmail.com | O21: 3312415016 | P21: =IF(A21="","", "DARINKA UREÑA CASILLAS") -> DARINKA UREÑA CASILLAS | Q21: =IF(D21="","",VLOOKUP(MONTH(D21),Listas!$C$2:$D$14,2,0)) -> Octubre | R21: =IF(D21="","",YEAR(D21)) -> 2020 | S21: =IF(D21="","",(DAY(D21))) -> 21 | T21: =IF(D21="","",S21-$W$1) -> 21 | U21: =IF(D21="","",(MONTH(D21))) -> 10 | V21: =IF(I21="","",(DAY(I21))) -> 14 | W21: =IF(I21="","",V21-$W$1) -> 14 | X21: =IF(I21="","",(MONTH(I21))) -> 3 | Y21: =IF(D21="","",(MONTH(D21))) -> 10 | Z21: =IFERROR(IF(I21="","", DATEDIF(I21, TODAY(), "Y")),0) -> 4 | AA21: =IF(Z21="","", IFS(Z21 >= 61, "61+ años", Z21 >= 51, "51-60 años", Z21 >= 40, "40-50 años", Z21 >= 20, "20-39 años", TRUE, "-20 años")) -> -20 años
A22: ANA KAREN MUÑIZ CHAVEZ | B22: M | C22: Activo | D22: 44241 | E22: GM0000513096 | F22: =1542.83*12 -> 18513.96 | G22: MXN | H22: Mensual | I22: 44801 | K22: TD | L22: Gastos Médicos | M22: Practico | N22: lupithamuniz0015@gmail.com | O22: 3314946421 | P22: =IF(A22="","", "DARINKA UREÑA CASILLAS") -> DARINKA UREÑA CASILLAS | Q22: =IF(D22="","",VLOOKUP(MONTH(D22),Listas!$C$2:$D$14,2,0)) -> Febrero | R22: =IF(D22="","",YEAR(D22)) -> 2021 | S22: =IF(D22="","",(DAY(D22))) -> 14 | T22: =IF(D22="","",S22-$W$1) -> 14 | U22: =IF(D22="","",(MONTH(D22))) -> 2 | V22: =IF(I22="","",(DAY(I22))) -> 28 | W22: =IF(I22="","",V22-$W$1) -> 28 | X22: =IF(I22="","",(MONTH(I22))) -> 8 | Y22: =IF(D22="","",(MONTH(D22))) -> 2 | Z22: =IFERROR(IF(I22="","", DATEDIF(I22, TODAY(), "Y")),0) -> 3 | AA22: =IF(Z22="","", IFS(Z22 >= 61, "61+ años", Z22 >= 51, "51-60 años", Z22 >= 40, "40-50 años", Z22 >= 20, "20-39 años", TRUE, "-20 años")) -> -20 años
A23: ANA PAULA GONZALEZ LUNA NIÑO | B23: M | C23: Activo | D23: 44146 | E23: VI0002566080 | F23: =320.91*12*7.118 -> 27410.849 | G23: UDIS | H23: Mensual | I23: 44804 | K23: TD | L23: Vida | M23: Orvi | N23: apgln@hotmail.com | O23: 3312799019 | P23: =IF(A23="","", "DARINKA UREÑA CASILLAS") -> DARINKA UREÑA CASILLAS | Q23: =IF(D23="","",VLOOKUP(MONTH(D23),Listas!$C$2:$D$14,2,0)) -> Noviembre | R23: =IF(D23="","",YEAR(D23)) -> 2020 | S23: =IF(D23="","",(DAY(D23))) -> 11 | T23: =IF(D23="","",S23-$W$1) -> 11 | U23: =IF(D23="","",(MONTH(D23))) -> 11 | V23: =IF(I23="","",(DAY(I23))) -> 31 | W23: =IF(I23="","",V23-$W$1) -> 31 | X23: =IF(I23="","",(MONTH(I23))) -> 8 | Y23: =IF(D23="","",(MONTH(D23))) -> 11 | Z23: =IFERROR(IF(I23="","", DATEDIF(I23, TODAY(), "Y")),0) -> 3 | AA23: =IF(Z23="","", IFS(Z23 >= 61, "61+ años", Z23 >= 51, "51-60 años", Z23 >= 40, "40-50 años", Z23 >= 20, "20-39 años", TRUE, "-20 años")) -> -20 años
A24: ANDREA HERNANDEZ MERCADO | B24: M | C24: Activo | D24: 44278 | E24: VI0002591407 | F24: =2143.12*7.118 -> 15254.728 | G24: UDIS | H24: ANUAL | I24: 06-sep | K24: TC | L24: Vida | M24: Orvi | N24: andreahdz_09@hotmail.com | O24: 3353312319 | P24: =IF(A24="","", "DARINKA UREÑA CASILLAS") -> DARINKA UREÑA CASILLAS | Q24: =IF(D24="","",VLOOKUP(MONTH(D24),Listas!$C$2:$D$14,2,0)) -> Marzo | R24: =IF(D24="","",YEAR(D24)) -> 2021 | S24: =IF(D24="","",(DAY(D24))) -> 23 | T24: =IF(D24="","",S24-$W$1) -> 23 | U24: =IF(D24="","",(MONTH(D24))) -> 3 | V24: =IF(I24="","",(DAY(I24))) -> 6 | W24: =IF(I24="","",V24-$W$1) -> 6 | X24: =IF(I24="","",(MONTH(I24))) -> 9 | Y24: =IF(D24="","",(MONTH(D24))) -> 3 | Z24: =IFERROR(IF(I24="","", DATEDIF(I24, TODAY(), "Y")),0) -> 0 | AA24: =IF(Z24="","", IFS(Z24 >= 61, "61+ años", Z24 >= 51, "51-60 años", Z24 >= 40, "40-50 años", Z24 >= 20, "20-39 años", TRUE, "-20 años")) -> -20 años
A25: ANGELICA ALEJANDRA SANCHEZ DURAN | B25: M | C25: Activo | D25: 44185 | E25: VI0002573965 | F25: =709.12*4*7.118 -> 20190.065 | G25: UDIS | H25: Trimestral | I25: 44596 | K25: TC | L25: Vida | M25: Orvi | N25: angelicaduran.4@hotmail.com | O25: 3314077658 | P25: =IF(A25="","", "DARINKA UREÑA CASILLAS") -> DARINKA UREÑA CASILLAS | Q25: =IF(D25="","",VLOOKUP(MONTH(D25),Listas!$C$2:$D$14,2,0)) -> Diciembre | R25: =IF(D25="","",YEAR(D25)) -> 2020 | S25: =IF(D25="","",(DAY(D25))) -> 20 | T25: =IF(D25="","",S25-$W$1) -> 20 | U25: =IF(D25="","",(MONTH(D25))) -> 12 | V25: =IF(I25="","",(DAY(I25))) -> 4 | W25: =IF(I25="","",V25-$W$1) -> 4 | X25: =IF(I25="","",(MONTH(I25))) -> 2 | Y25: =IF(D25="","",(MONTH(D25))) -> 12 | Z25: =IFERROR(IF(I25="","", DATEDIF(I25, TODAY(), "Y")),0) -> 4 | AA25: =IF(Z25="","", IFS(Z25 >= 61, "61+ años", Z25 >= 51, "51-60 años", Z25 >= 40, "40-50 años", Z25 >= 20, "20-39 años", TRUE, "-20 años")) -> -20 años
A26: ARNOLD SANCHEZ SANCHEZ | B26: H | C26: Activo | D26: 43878 | E26: VI0002517934 | F26: =163.05*12*7.118 -> 13927.079 | G26: UDIS | H26: Mensual | I26: 44605 | K26: TC | L26: Vida | M26: Orvi | N26: sanchez.201024835@outlook.com | O26: 2223716744 | P26: =IF(A26="","", "DARINKA UREÑA CASILLAS") -> DARINKA UREÑA CASILLAS | Q26: =IF(D26="","",VLOOKUP(MONTH(D26),Listas!$C$2:$D$14,2,0)) -> Febrero | R26: =IF(D26="","",YEAR(D26)) -> 2020 | S26: =IF(D26="","",(DAY(D26))) -> 17 | T26: =IF(D26="","",S26-$W$1) -> 17 | U26: =IF(D26="","",(MONTH(D26))) -> 2 | V26: =IF(I26="","",(DAY(I26))) -> 13 | W26: =IF(I26="","",V26-$W$1) -> 13 | X26: =IF(I26="","",(MONTH(I26))) -> 2 | Y26: =IF(D26="","",(MONTH(D26))) -> 2 | Z26: =IFERROR(IF(I26="","", DATEDIF(I26, TODAY(), "Y")),0) -> 4 | AA26: =IF(Z26="","", IFS(Z26 >= 61, "61+ años", Z26 >= 51, "51-60 años", Z26 >= 40, "40-50 años", Z26 >= 20, "20-39 años", TRUE, "-20 años")) -> -20 años
A27: BERNARDO GARCIA GOMEZ | B27: H | C27: Activo | D27: 44859 | E27: VI0002697696 | F27: =7989.92*7.65 -> 61122.888 | G27: UDIS | H27: Anual | I27: 45225 | K27: TC | L27: Vida | M27: Imagina ser | N27: bernigarcia365@icloud.com | O27: 3317070106 | P27: =IF(A27="","", "DARINKA UREÑA CASILLAS") -> DARINKA UREÑA CASILLAS | Q27: =IF(D27="","",VLOOKUP(MONTH(D27),Listas!$C$2:$D$14,2,0)) -> Octubre | R27: =IF(D27="","",YEAR(D27)) -> 2022 | S27: =IF(D27="","",(DAY(D27))) -> 25 | T27: =IF(D27="","",S27-$W$1) -> 25 | U27: =IF(D27="","",(MONTH(D27))) -> 10 | V27: =IF(I27="","",(DAY(I27))) -> 26 | W27: =IF(I27="","",V27-$W$1) -> 26 | X27: =IF(I27="","",(MONTH(I27))) -> 10 | Y27: =IF(D27="","",(MONTH(D27))) -> 10 | Z27: =IFERROR(IF(I27="","", DATEDIF(I27, TODAY(), "Y")),0) -> 2 | AA27: =IF(Z27="","", IFS(Z27 >= 61, "61+ años", Z27 >= 51, "51-60 años", Z27 >= 40, "40-50 años", Z27 >= 20, "20-39 años", TRUE, "-20 años")) -> -20 años
A28: BERNARDO GARCIA GOMEZ | B28: H | C28: Activo | D28: 44859 | E28: VI0002698084 | F28: =3187.51*7.65 -> 24384.451 | G28: UDIS | H28: Anual | I28: 45225 | K28: TC | L28: Vida | M28: Orvi | N28: bernigarcia365@icloud.com | O28: 3317070106 | P28: =IF(A28="","", "DARINKA UREÑA CASILLAS") -> DARINKA UREÑA CASILLAS | Q28: =IF(D28="","",VLOOKUP(MONTH(D28),Listas!$C$2:$D$14,2,0)) -> Octubre | R28: =IF(D28="","",YEAR(D28)) -> 2022 | S28: =IF(D28="","",(DAY(D28))) -> 25 | T28: =IF(D28="","",S28-$W$1) -> 25 | U28: =IF(D28="","",(MONTH(D28))) -> 10 | V28: =IF(I28="","",(DAY(I28))) -> 26 | W28: =IF(I28="","",V28-$W$1) -> 26 | X28: =IF(I28="","",(MONTH(I28))) -> 10 | Y28: =IF(D28="","",(MONTH(D28))) -> 10 | Z28: =IFERROR(IF(I28="","", DATEDIF(I28, TODAY(), "Y")),0) -> 2 | AA28: =IF(Z28="","", IFS(Z28 >= 61, "61+ años", Z28 >= 51, "51-60 años", Z28 >= 40, "40-50 años", Z28 >= 20, "20-39 años", TRUE, "-20 años")) -> -20 años
A29: BETH SUA MONTEJANO CARMONA | B29: M | C29: Activo | D29: 44104 | E29: VI0002558023 | F29: =3665.66*7.118 -> 26092.168 | G29: UDIS | H29: Anual | I29: 17-sep | K29: TC | L29: Vida | M29: Orvi | N29: moncar1709@gmail.com | O29: 3313875424 | P29: =IF(A29="","", "DARINKA UREÑA CASILLAS") -> DARINKA UREÑA CASILLAS | Q29: =IF(D29="","",VLOOKUP(MONTH(D29),Listas!$C$2:$D$14,2,0)) -> Septiembre | R29: =IF(D29="","",YEAR(D29)) -> 2020 | S29: =IF(D29="","",(DAY(D29))) -> 30 | T29: =IF(D29="","",S29-$W$1) -> 30 | U29: =IF(D29="","",(MONTH(D29))) -> 9 | V29: =IF(I29="","",(DAY(I29))) -> 17 | W29: =IF(I29="","",V29-$W$1) -> 17 | X29: =IF(I29="","",(MONTH(I29))) -> 9 | Y29: =IF(D29="","",(MONTH(D29))) -> 9 | Z29: =IFERROR(IF(I29="","", DATEDIF(I29, TODAY(), "Y")),0) -> 0 | AA29: =IF(Z29="","", IFS(Z29 >= 61, "61+ años", Z29 >= 51, "51-60 años", Z29 >= 40, "40-50 años", Z29 >= 20, "20-39 años", TRUE, "-20 años")) -> -20 años
A30: BLANCA CAROLINA MAGAÑA CASTELLON | B30: M | C30: Activo | D30: 44930 | E30: GM0000588897 | F30: =8616.38*4 -> 34465.52 | G30: MXN | H30: Trimestral | I30: 45131 | K30: AGENTE | L30: Gastos Médicos | M30: Integro | N30: aideflores.arellano@gmail.com | O30: 3314239602 | P30: =IF(A30="","", "DARINKA UREÑA CASILLAS") -> DARINKA UREÑA CASILLAS | Q30: =IF(D30="","",VLOOKUP(MONTH(D30),Listas!$C$2:$D$14,2,0)) -> Enero | R30: =IF(D30="","",YEAR(D30)) -> 2023 | S30: =IF(D30="","",(DAY(D30))) -> 4 | T30: =IF(D30="","",S30-$W$1) -> 4 | U30: =IF(D30="","",(MONTH(D30))) -> 1 | V30: =IF(I30="","",(DAY(I30))) -> 24 | W30: =IF(I30="","",V30-$W$1) -> 24 | X30: =IF(I30="","",(MONTH(I30))) -> 7 | Y30: =IF(D30="","",(MONTH(D30))) -> 1 | Z30: =IFERROR(IF(I30="","", DATEDIF(I30, TODAY(), "Y")),0) -> 2 | AA30: =IF(Z30="","", IFS(Z30 >= 61, "61+ años", Z30 >= 51, "51-60 años", Z30 >= 40, "40-50 años", Z30 >= 20, "20-39 años", TRUE, "-20 años")) -> -20 años
A31: CARLA ANDREA MARTINEZ LAGOS | B31: M | C31: Activo | D31: 44632 | E31: VI0002654798 | F31: 36597.675 | G31: UDIS | H31: Anual | I31: 44938 | K31: TD | L31: Vida | M31: Orvi | N31: carla.martineez@hotmail.com | O31: 3334453680 | P31: =IF(A31="","", "DARINKA UREÑA CASILLAS") -> DARINKA UREÑA CASILLAS | Q31: =IF(D31="","",VLOOKUP(MONTH(D31),Listas!$C$2:$D$14,2,0)) -> Marzo | R31: =IF(D31="","",YEAR(D31)) -> 2022 | S31: =IF(D31="","",(DAY(D31))) -> 12 | T31: =IF(D31="","",S31-$W$1) -> 12 | U31: =IF(D31="","",(MONTH(D31))) -> 3 | V31: =IF(I31="","",(DAY(I31))) -> 12 | W31: =IF(I31="","",V31-$W$1) -> 12 | X31: =IF(I31="","",(MONTH(I31))) -> 1 | Y31: =IF(D31="","",(MONTH(D31))) -> 3 | Z31: =IFERROR(IF(I31="","", DATEDIF(I31, TODAY(), "Y")),0) -> 3 | AA31: =IF(Z31="","", IFS(Z31 >= 61, "61+ años", Z31 >= 51, "51-60 años", Z31 >= 40, "40-50 años", Z31 >= 20, "20-39 años", TRUE, "-20 años")) -> -20 años
A32: CARLOS ALBERTO MORALES NOGUEDA | B32: M | C32: Activo | D32: 44773 | E32: VI0002682439 | F32: =3240*7.65 -> 24786 | G32: UDIS | H32: Anual | I32: 44989 | K32: TC | L32: Vida | M32: Segubeca | N32: walazamn@hotmail.com | O32: 3314537802 | P32: =IF(A32="","", "DARINKA UREÑA CASILLAS") -> DARINKA UREÑA CASILLAS | Q32: =IF(D32="","",VLOOKUP(MONTH(D32),Listas!$C$2:$D$14,2,0)) -> Julio | R32: =IF(D32="","",YEAR(D32)) -> 2022 | S32: =IF(D32="","",(DAY(D32))) -> 31 | T32: =IF(D32="","",S32-$W$1) -> 31 | U32: =IF(D32="","",(MONTH(D32))) -> 7 | V32: =IF(I32="","",(DAY(I32))) -> 4 | W32: =IF(I32="","",V32-$W$1) -> 4 | X32: =IF(I32="","",(MONTH(I32))) -> 3 | Y32: =IF(D32="","",(MONTH(D32))) -> 7 | Z32: =IFERROR(IF(I32="","", DATEDIF(I32, TODAY(), "Y")),0) -> 3 | AA32: =IF(Z32="","", IFS(Z32 >= 61, "61+ años", Z32 >= 51, "51-60 años", Z32 >= 40, "40-50 años", Z32 >= 20, "20-39 años", TRUE, "-20 años")) -> -20 años
A33: CARLOS CASTRO PALAZUELOS | B33: H | C33: Activo | D33: 44677 | E33: VI0002662475 | F33: =441.69*12*7.31 -> 38745.047 | G33: UDIS | H33: Mensual | I33: 45101 | K33: TC | L33: Vida | M33: Orvi | N33: tekilopalazuelos@gmail.com | O33: 9985779227 | P33: =IF(A33="","", "DARINKA UREÑA CASILLAS") -> DARINKA UREÑA CASILLAS | Q33: =IF(D33="","",VLOOKUP(MONTH(D33),Listas!$C$2:$D$14,2,0)) -> Abril | R33: =IF(D33="","",YEAR(D33)) -> 2022 | S33: =IF(D33="","",(DAY(D33))) -> 26 | T33: =IF(D33="","",S33-$W$1) -> 26 | U33: =IF(D33="","",(MONTH(D33))) -> 4 | V33: =IF(I33="","",(DAY(I33))) -> 24 | W33: =IF(I33="","",V33-$W$1) -> 24 | X33: =IF(I33="","",(MONTH(I33))) -> 6 | Y33: =IF(D33="","",(MONTH(D33))) -> 4 | Z33: =IFERROR(IF(I33="","", DATEDIF(I33, TODAY(), "Y")),0) -> 2 | AA33: =IF(Z33="","", IFS(Z33 >= 61, "61+ años", Z33 >= 51, "51-60 años", Z33 >= 40, "40-50 años", Z33 >= 20, "20-39 años", TRUE, "-20 años")) -> -20 años
A34: CARLOS DAVID AVILA URRUCHUA | B34: H | C34: Activo | D34: 44389 | E34: VI0002613039 | F34: =793.59*12*7.118 -> 67785.283 | G34: UDIS | H34: Mensual | I34: 12-sep | K34: TD | L34: Vida | M34: Segubeca | N34: carlos_a_u@hotmail.com | O34: 9841309280 | P34: =IF(A34="","", "DARINKA UREÑA CASILLAS") -> DARINKA UREÑA CASILLAS | Q34: =IF(D34="","",VLOOKUP(MONTH(D34),Listas!$C$2:$D$14,2,0)) -> Julio | R34: =IF(D34="","",YEAR(D34)) -> 2021 | S34: =IF(D34="","",(DAY(D34))) -> 12 | T34: =IF(D34="","",S34-$W$1) -> 12 | U34: =IF(D34="","",(MONTH(D34))) -> 7 | V34: =IF(I34="","",(DAY(I34))) -> 12 | W34: =IF(I34="","",V34-$W$1) -> 12 | X34: =IF(I34="","",(MONTH(I34))) -> 9 | Y34: =IF(D34="","",(MONTH(D34))) -> 7 | Z34: =IFERROR(IF(I34="","", DATEDIF(I34, TODAY(), "Y")),0) -> 0 | AA34: =IF(Z34="","", IFS(Z34 >= 61, "61+ años", Z34 >= 51, "51-60 años", Z34 >= 40, "40-50 años", Z34 >= 20, "20-39 años", TRUE, "-20 años")) -> -20 años
A35: CARLOS HUMBERTO VILLANUEVA CARMONA | B35: H | C35: Activo | D35: 44646 | E35: VI0002657416 | F35: =228.16*12*7.24 -> 19822.541 | G35: UDIS | H35: Mensual | I35: 44810 | K35: TC | L35: Vida | M35: Orvi | N35: carloshum3888@gmail.com | O35: 3313033649 | P35: =IF(A35="","", "DARINKA UREÑA CASILLAS") -> DARINKA UREÑA CASILLAS | Q35: =IF(D35="","",VLOOKUP(MONTH(D35),Listas!$C$2:$D$14,2,0)) -> Marzo | R35: =IF(D35="","",YEAR(D35)) -> 2022 | S35: =IF(D35="","",(DAY(D35))) -> 26 | T35: =IF(D35="","",S35-$W$1) -> 26 | U35: =IF(D35="","",(MONTH(D35))) -> 3 | V35: =IF(I35="","",(DAY(I35))) -> 6 | W35: =IF(I35="","",V35-$W$1) -> 6 | X35: =IF(I35="","",(MONTH(I35))) -> 9 | Y35: =IF(D35="","",(MONTH(D35))) -> 3 | Z35: =IFERROR(IF(I35="","", DATEDIF(I35, TODAY(), "Y")),0) -> 3 | AA35: =IF(Z35="","", IFS(Z35 >= 61, "61+ años", Z35 >= 51, "51-60 años", Z35 >= 40, "40-50 años", Z35 >= 20, "20-39 años", TRUE, "-20 años")) -> -20 años
A36: CARLOS VERDUZO FAVELA | B36: H | C36: Activo | D36: 44831 | E36: VI0002692302 | F36: =2540.52*2*7.65 -> 38869.956 | G36: UDIS | H36: Semestral | I36: 45137 | K36: TD | L36: Vida | M36: Orvi | N36: carlos.verduzcof@gmail.com | O36: 3316696345 | P36: =IF(A36="","", "DARINKA UREÑA CASILLAS") -> DARINKA UREÑA CASILLAS | Q36: =IF(D36="","",VLOOKUP(MONTH(D36),Listas!$C$2:$D$14,2,0)) -> Septiembre | R36: =IF(D36="","",YEAR(D36)) -> 2022 | S36: =IF(D36="","",(DAY(D36))) -> 27 | T36: =IF(D36="","",S36-$W$1) -> 27 | U36: =IF(D36="","",(MONTH(D36))) -> 9 | V36: =IF(I36="","",(DAY(I36))) -> 30 | W36: =IF(I36="","",V36-$W$1) -> 30 | X36: =IF(I36="","",(MONTH(I36))) -> 7 | Y36: =IF(D36="","",(MONTH(D36))) -> 9 | Z36: =IFERROR(IF(I36="","", DATEDIF(I36, TODAY(), "Y")),0) -> 2 | AA36: =IF(Z36="","", IFS(Z36 >= 61, "61+ años", Z36 >= 51, "51-60 años", Z36 >= 40, "40-50 años", Z36 >= 20, "20-39 años", TRUE, "-20 años")) -> -20 años
A37: CARLOS XAVIER BARBA LOPEZ | B37: H | C37: Activo | D37: 44560 | E37: GM0000549543 | F37: =4581.86*4 -> 18327.44 | G37: MXN | H37: Trimestral | I37: 44713 | K37: TD | L37: Gastos Médicos | M37: Integro | N37: eagletijuana@gmail.com | O37: 3324962545 | P37: =IF(A37="","", "DARINKA UREÑA CASILLAS") -> DARINKA UREÑA CASILLAS | Q37: =IF(D37="","",VLOOKUP(MONTH(D37),Listas!$C$2:$D$14,2,0)) -> Diciembre | R37: =IF(D37="","",YEAR(D37)) -> 2021 | S37: =IF(D37="","",(DAY(D37))) -> 30 | T37: =IF(D37="","",S37-$W$1) -> 30 | U37: =IF(D37="","",(MONTH(D37))) -> 12 | V37: =IF(I37="","",(DAY(I37))) -> 1 | W37: =IF(I37="","",V37-$W$1) -> 1 | X37: =IF(I37="","",(MONTH(I37))) -> 6 | Y37: =IF(D37="","",(MONTH(D37))) -> 12 | Z37: =IFERROR(IF(I37="","", DATEDIF(I37, TODAY(), "Y")),0) -> 3 | AA37: =IF(Z37="","", IFS(Z37 >= 61, "61+ años", Z37 >= 51, "51-60 años", Z37 >= 40, "40-50 años", Z37 >= 20, "20-39 años", TRUE, "-20 años")) -> -20 años
A38: CECILIA ARCEO CERVANTES | B38: M | C38: Activo | D38: 44333 | E38: VI0002601742 | F38: =2266.93*2*7.118 -> 32272.015 | G38: UDIS | H38: Semestral | I38: 44877 | K38: TC | L38: Vida | M38: Orvi | N38: cecyarceo@hotmail.com | O38: 3311741926 | P38: =IF(A38="","", "DARINKA UREÑA CASILLAS") -> DARINKA UREÑA CASILLAS | Q38: =IF(D38="","",VLOOKUP(MONTH(D38),Listas!$C$2:$D$14,2,0)) -> Mayo | R38: =IF(D38="","",YEAR(D38)) -> 2021 | S38: =IF(D38="","",(DAY(D38))) -> 17 | T38: =IF(D38="","",S38-$W$1) -> 17 | U38: =IF(D38="","",(MONTH(D38))) -> 5 | V38: =IF(I38="","",(DAY(I38))) -> 12 | W38: =IF(I38="","",V38-$W$1) -> 12 | X38: =IF(I38="","",(MONTH(I38))) -> 11 | Y38: =IF(D38="","",(MONTH(D38))) -> 5 | Z38: =IFERROR(IF(I38="","", DATEDIF(I38, TODAY(), "Y")),0) -> 3 | AA38: =IF(Z38="","", IFS(Z38 >= 61, "61+ años", Z38 >= 51, "51-60 años", Z38 >= 40, "40-50 años", Z38 >= 20, "20-39 años", TRUE, "-20 años")) -> -20 años
A39: CESAR ISRRAEL HERNANDEZ SANCHEZ | B39: H | C39: Activo | D39: 44728 | E39: VI0002672529 | F39: =3194.49*4*7.41 -> 94684.684 | G39: UDIS | H39: Trimestral | I39: 45163 | K39: TD | L39: Vida | M39: Orvi | N39: cesar25941@outlook.com | O39: 3311249925 | P39: =IF(A39="","", "DARINKA UREÑA CASILLAS") -> DARINKA UREÑA CASILLAS | Q39: =IF(D39="","",VLOOKUP(MONTH(D39),Listas!$C$2:$D$14,2,0)) -> Junio | R39: =IF(D39="","",YEAR(D39)) -> 2022 | S39: =IF(D39="","",(DAY(D39))) -> 16 | T39: =IF(D39="","",S39-$W$1) -> 16 | U39: =IF(D39="","",(MONTH(D39))) -> 6 | V39: =IF(I39="","",(DAY(I39))) -> 25 | W39: =IF(I39="","",V39-$W$1) -> 25 | X39: =IF(I39="","",(MONTH(I39))) -> 8 | Y39: =IF(D39="","",(MONTH(D39))) -> 6 | Z39: =IFERROR(IF(I39="","", DATEDIF(I39, TODAY(), "Y")),0) -> 2 | AA39: =IF(Z39="","", IFS(Z39 >= 61, "61+ años", Z39 >= 51, "51-60 años", Z39 >= 40, "40-50 años", Z39 >= 20, "20-39 años", TRUE, "-20 años")) -> -20 años
A40: CESAR ISRRAEL HERNANDEZ SANCHEZ | B40: M | C40: Activo | D40: 44755 | E40: VI0002678390 | F40: =1091.28*2*7.41 -> 16172.77 | G40: UDIS | H40: Semestral | I40: 45127 | K40: TD | L40: Vida | M40: Orvi | N40: cesar25941@outlook.com | O40: 3311249925 | P40: =IF(A40="","", "DARINKA UREÑA CASILLAS") -> DARINKA UREÑA CASILLAS | Q40: =IF(D40="","",VLOOKUP(MONTH(D40),Listas!$C$2:$D$14,2,0)) -> Julio | R40: =IF(D40="","",YEAR(D40)) -> 2022 | S40: =IF(D40="","",(DAY(D40))) -> 13 | T40: =IF(D40="","",S40-$W$1) -> 13 | U40: =IF(D40="","",(MONTH(D40))) -> 7 | V40: =IF(I40="","",(DAY(I40))) -> 20 | W40: =IF(I40="","",V40-$W$1) -> 20 | X40: =IF(I40="","",(MONTH(I40))) -> 7 | Y40: =IF(D40="","",(MONTH(D40))) -> 7 | Z40: =IFERROR(IF(I40="","", DATEDIF(I40, TODAY(), "Y")),0) -> 2 | AA40: =IF(Z40="","", IFS(Z40 >= 61, "61+ años", Z40 >= 51, "51-60 años", Z40 >= 40, "40-50 años", Z40 >= 20, "20-39 años", TRUE, "-20 años")) -> -20 años
A41: CINTHIA NOEMI JASSO TORRES | B41: M | C41: Activo | D41: 44826 | E41: VI0002690934 | F41: =425.4*7.65*12 -> 39051.72 | G41: UDIS | H41: Mensual | I41: 45276 | K41: TC | L41: Vida | M41: Orvi | N41: noemijass1982@gmail.com | O41: 3321643018 | P41: =IF(A41="","", "DARINKA UREÑA CASILLAS") -> DARINKA UREÑA CASILLAS | Q41: =IF(D41="","",VLOOKUP(MONTH(D41),Listas!$C$2:$D$14,2,0)) -> Septiembre | R41: =IF(D41="","",YEAR(D41)) -> 2022 | S41: =IF(D41="","",(DAY(D41))) -> 22 | T41: =IF(D41="","",S41-$W$1) -> 22 | U41: =IF(D41="","",(MONTH(D41))) -> 9 | V41: =IF(I41="","",(DAY(I41))) -> 16 | W41: =IF(I41="","",V41-$W$1) -> 16 | X41: =IF(I41="","",(MONTH(I41))) -> 12 | Y41: =IF(D41="","",(MONTH(D41))) -> 9 | Z41: =IFERROR(IF(I41="","", DATEDIF(I41, TODAY(), "Y")),0) -> 2 | AA41: =IF(Z41="","", IFS(Z41 >= 61, "61+ años", Z41 >= 51, "51-60 años", Z41 >= 40, "40-50 años", Z41 >= 20, "20-39 años", TRUE, "-20 años")) -> -20 años
A42: CLAUDIO ALBERTO MARTIN LOPEZ | B42: H | C42: Activo | D42: 44616 | E42: VI0002652270 | F42: 60000 | G42: UDIS | H42: Semestral | I42: 44952 | K42: TC | L42: Vida | M42: Orvi | N42: innsmouth26@gmail.com | O42: 3311582572 | P42: =IF(A42="","", "DARINKA UREÑA CASILLAS") -> DARINKA UREÑA CASILLAS | Q42: =IF(D42="","",VLOOKUP(MONTH(D42),Listas!$C$2:$D$14,2,0)) -> Febrero | R42: =IF(D42="","",YEAR(D42)) -> 2022 | S42: =IF(D42="","",(DAY(D42))) -> 24 | T42: =IF(D42="","",S42-$W$1) -> 24 | U42: =IF(D42="","",(MONTH(D42))) -> 2 | V42: =IF(I42="","",(DAY(I42))) -> 26 | W42: =IF(I42="","",V42-$W$1) -> 26 | X42: =IF(I42="","",(MONTH(I42))) -> 1 | Y42: =IF(D42="","",(MONTH(D42))) -> 2 | Z42: =IFERROR(IF(I42="","", DATEDIF(I42, TODAY(), "Y")),0) -> 3 | AA42: =IF(Z42="","", IFS(Z42 >= 61, "61+ años", Z42 >= 51, "51-60 años", Z42 >= 40, "40-50 años", Z42 >= 20, "20-39 años", TRUE, "-20 años")) -> -20 años
...

Sheet Asegurados
A5: Cliente | B5: Número de póliza | C5: Nombre Asegurado | D5: Parentesco | E5: Cumpleaños | F5: Mes Cumpleaños
B6: =IF(A6="","",VLOOKUP(A6,'BD Asesor'!$A$8:$E$1998,5,0)) | F6: =IF(E6="","",(MONTH(E6)))
B7: =IF(A7="","",VLOOKUP(A7,'BD Asesor'!$A$8:$E$1998,5,0)) | F7: =IF(E7="","",(MONTH(E7)))
B8: =IF(A8="","",VLOOKUP(A8,'BD Asesor'!$A$8:$E$1998,5,0)) | F8: =IF(E8="","",(MONTH(E8)))
B9: =IF(A9="","",VLOOKUP(A9,'BD Asesor'!$A$8:$E$1998,5,0)) | F9: =IF(E9="","",(MONTH(E9)))
B10: =IF(A10="","",VLOOKUP(A10,'BD Asesor'!$A$8:$E$1998,5,0)) | F10: =IF(E10="","",(MONTH(E10)))
B11: =IF(A11="","",VLOOKUP(A11,'BD Asesor'!$A$8:$E$1998,5,0)) | F11: =IF(E11="","",(MONTH(E11)))
B12: =IF(A12="","",VLOOKUP(A12,'BD Asesor'!$A$8:$E$1998,5,0)) | F12: =IF(E12="","",(MONTH(E12)))
B13: =IF(A13="","",VLOOKUP(A13,'BD Asesor'!$A$8:$E$1998,5,0)) | F13: =IF(E13="","",(MONTH(E13)))
B14: =IF(A14="","",VLOOKUP(A14,'BD Asesor'!$A$8:$E$1998,5,0)) | F14: =IF(E14="","",(MONTH(E14)))
B15: =IF(A15="","",VLOOKUP(A15,'BD Asesor'!$A$8:$E$1998,5,0)) | F15: =IF(E15="","",(MONTH(E15)))
B16: =IF(A16="","",VLOOKUP(A16,'BD Asesor'!$A$8:$E$1998,5,0)) | F16: =IF(E16="","",(MONTH(E16)))
B17: =IF(A17="","",VLOOKUP(A17,'BD Asesor'!$A$8:$E$1998,5,0)) | F17: =IF(E17="","",(MONTH(E17)))
... B1000: =IF(A1000="","",VLOOKUP(A1000,'BD Asesor'!$A$8:$E$1998,5,0)) | F1000: =IF(E1000="","",(MONTH(E1000)))

Sheet Prospectos
C4: 15 dias antes
C5: Hoy | G5: Tabla de Status | L5: Tabla de Fuente | P5: Tabla de Referenciados | S5: Tabla de Grupo de Referidos
C6: Vencido
A7: Prospecto | B7: Fuente | C7: Siguiente Contacto | D7: Referenciado por | E7: Diferencia de dia | F7: TELEFONO | G7: STATUS | H7: Status | I7: Prospecto | J7: Porcentaje | L7: Fuente | M7: Prospecto | N7: Porcentaje
A8: AMAURI | B8: Referido | C8: 44595 | D8: DR. BARRAGAN | E8: =IF(C8 ="","",C8-Listas!$B$2) -> -1566 | F8: 3313014779 | G8: Cita cierre | H8: Cerrado | I8: =COUNTIF($A$7:$D$1000,H8) -> 0 | J8: =I8/$I$12 -> #DIV/0! | L8: Mercado cálido | M8: =COUNTIF($A$7:$D$1000,L8) -> 0 | N8: =M8/$I$12 -> #DIV/0!
A9: DR. JIMENEZ | B9: Referido | C9: 44601 | D9: DR. BARRAGAN | E9: =IF(C9 ="","",C9-Listas!$B$2) -> -1560 | F9: 3336260468 | G9: Cita cierre | H9: Cita de cierre | I9: =COUNTIF($A$7:$D$1000,H9) -> 0 | J9: =I9/$I$12 -> #DIV/0! | L9: Redes sociales | M9: =COUNTIF($A$7:$D$1000,L9) -> 0 | N9: =M9/$I$12 -> #DIV/0!
A10: DR.CARDE | B10: Referido | C10: 44600 | D10: DR. BARRAGAN | E10: =IF(C10 ="","",C10-Listas!$B$2) -> -1561 | F10: 3316727678 | G10: CITA INICIAL | H10: Cita inicial | I10: =COUNTIF($A$7:$D$1000,H10) -> 0 | J10: =I10/$I$12 -> #DIV/0! | L10: Referido | M10: =COUNTIF($A$7:$D$1000,L10) -> 327 | N10: =M10/$I$12 -> #DIV/0!
A11: DR. ISLAS | B11: Referido | C11: X | D11: DR. BARRAGAN | E11: =IF(C11 ="","",C11-Listas!$B$2) -> #VALUE! | F11: 3310440720 | G11: LLAMAR | H11: Contactado | I11: =COUNTIF($A$7:$D$1000,H11) -> 0 | J11: =I11/$I$12 -> #DIV/0! | L11: Otro | M11: =COUNTIF($A$7:$D$1000,L11) -> 0 | N11: =M11/$I$12 -> #DIV/0!
A12: DR. NAVA | B12: Referido | C12: X | D12: DR. BARRAGAN | E12: =IF(C12 ="","",C12-Listas!$B$2) -> #VALUE! | F12: 3313038073 | G12: X | H12: Total | I12: =SUM(I8:I11) -> 0 | J12: =SUM(J8:J11) -> #DIV/0! | L12: Total | M12: =SUM(M8:M11) -> 327 | N12: =SUM(N8:N11) -> #DIV/0!
A13: LUIS FERNANDO | B13: Referido | C13: X | D13: CLAUDIO MARTIN | E13: =IF(C13 ="","",C13-Listas!$B$2) -> #VALUE! | F13: 3311690262 | G13: 19 DE MAYO
A14: FRANCISCO | B14: Referido | C14: PLAN ORVI | D14: CLAUDIO MARTIN | E14: =IF(C14 ="","",C14-Listas!$B$2) -> #VALUE! | F14: 3331675304 | G14: CERRADO
A15: JOSE ANTONIO | B15: Referido | C15: YA TIENE PLANES | D15: CLAUDIO MARTIN | E15: =IF(C15 ="","",C15-Listas!$B$2) -> #VALUE! | F15: 3313591320 | G15: 19 DE MAYO
A16: MAELY SASSO | B16: Referido | C16: X | D16: CLAUDIO MARTIN | E16: =IF(C16 ="","",C16-Listas!$B$2) -> #VALUE! | F16: 3314257494 | G16: 25 DE ABRIL
A17: JUAN PABLO | B17: Referido | C17: X | D17: CLAUDIO MARTIN | E17: =IF(C17 ="","",C17-Listas!$B$2) -> #VALUE! | F17: 3311868613 | G17: X
A18: MIGUEL TABLON | B18: Referido | C18: X | D18: CLAUDIO MARTIN | E18: =IF(C18 ="","",C18-Listas!$B$2) -> #VALUE! | F18: 3311768094 | G18: X
A19: ADAN | B19: Referido | C19: X | D19: CARLA MARTINEZ | E19: =IF(C19 ="","",C19-Listas!$B$2) -> #VALUE! | F19: 3312693025 | G19: 01 DE ABRIL 2025
A20: ALANIS | B20: Referido | C20: X | D20: CARLA MARTINEZ | E20: =IF(C20 ="","",C20-Listas!$B$2) -> #VALUE! | F20: 3311769244 | G20: 2 DE ENERO 2025
A21: ALE MEZA | B21: Referido | C21: X | D21: CARLA MARTINEZ | E21: =IF(C21 ="","",C21-Listas!$B$2) -> #VALUE! | F21: 3334560402 | G21: 12 DE FEBRERO 2025
A22: ALEX | B22: Referido | C22: X | D22: CARLA MARTINEZ | E22: =IF(C22 ="","",C22-Listas!$B$2) -> #VALUE! | F22: 3339548158 | G22: 5 DE FEBRERO 2025
A23: ALEX GMM | B23: Referido | C23: X | D23: CARLA MARTINEZ | E23: =IF(C23 ="","",C23-Listas!$B$2) -> #VALUE! | F23: 3319165772 | G23: 01 DE ABRIL 2025
A24: ALICIA | B24: Referido | C24: YA TIENE PLANES | D24: CARLA MARTINEZ | E24: =IF(C24 ="","",C24-Listas!$B$2) -> #VALUE! | F24: 3311105038 | G24: 2 DE ENERO 2025
... A26: ANA | B26: Referido | C26: X | D26: CARLA MARTINEZ | E26: =IF(C26 ="","",C26-Listas!$B$2) -> #VALUE! | F26: 3317879808 | G26: 14 DE ENERO 2025
A27: ANGIE | B27: Referido | C27: NO CONTESTA | D27: CARLA MARTINEZ | E27: =IF(C27 ="","",C27-Listas!$B$2) -> #VALUE! | F27: X | G27: 2 DE ENERO 2025
A28: X | B28: Referido | C28: PREGUNTAR NOMBRE | D28: CARLA MARTINEZ | E28: =IF(C28 ="","",C28-Listas!$B$2) -> #VALUE! | F28: 3310384826 | G28: 2 DE ENERO 2025
A29: BETO ROMO | B29: Referido | C29: X | D29: CARLA MARTINEZ | E29: =IF(C29 ="","",C29-Listas!$B$2) -> #VALUE! | F29: 33 1822 9636 | G29: 12 DE FEBRERO 2025
A30: CESAR | B30: Referido | C30: NO LE INTERESA | D30: CARLA MARTINEZ | E30: =IF(C30 ="","",C30-Listas!$B$2) -> #VALUE! | F30: 33 1286 5078 | G30: 2 DE ENERO 2025
A31: CHARLIE | B31: Referido | C31: X | D31: CARLA MARTINEZ | E31: =IF(C31 ="","",C31-Listas!$B$2) -> #VALUE! | F31: 664 335 4558 | G31: 5 DE FEBERO 2025
A32: JOSE | B32: Referido | C32: X | D32: CARLA MARTINEZ | E32: =IF(C32 ="","",C32-Listas!$B$2) -> #VALUE! | F32: 33 1431 7950 | G32: 2 DE ENERO 2025
A33: CHAVA CHIVAS | B33: Referido | C33: X | D33: CARLA MARTINEZ | E33: =IF(C33 ="","",C33-Listas!$B$2) -> #VALUE! | F33: 33 3839 8680 | G33: 01 DE ABRIL 2025
A34: CRIS BRAMBILA | B34: Referido | C34: YA TIENE PPR Y VARIOS PLANES | D34: CARLA MARTINEZ | E34: =IF(C34 ="","",C34-Listas!$B$2) -> #VALUE! | F34: 33 3167 5044 | G34: 2 DE ENERO 2025
A35: DAVID ALEX | B35: Referido | C35: X | D35: CARLA MARTINEZ | E35: =IF(C35 ="","",C35-Listas!$B$2) -> #VALUE! | F35: 33 1573 9184 | G35: 01 DE ABRIL 2025
A36: DENTISTA VERO | B36: Referido | C36: x | D36: CARLA MARTINEZ | E36: =IF(C36 ="","",C36-Listas!$B$2) -> #VALUE! | F36: 33 3508 6396 | G36: 01 DE ABRIL 2025
A37: DIANA | B37: Referido | C37: X | D37: CARLA MARTINEZ | E37: =IF(C37 ="","",C37-Listas!$B$2) -> #VALUE! | F37: 33 1822 5060 | G37: 01 DE ABRIL 2025
A38: DIANA OCAMPO | B38: Referido | C38: JUSTO CONTRATO GMM | D38: CARLA MARTINEZ | E38: =IF(C38 ="","",C38-Listas!$B$2) -> #VALUE! | F38: 33 1255 7032 | G38: 01 DE ABRIL 2025
A39: DIEGO CIRQUE | B39: Referido | C39: X | D39: CARLA MARTINEZ | E39: =IF(C39 ="","",C39-Listas!$B$2) -> #VALUE! | F39: 33 1976 5481 | G39: 02 DE ABRIL 2025
A40: EDGAR ALTEA | B40: Referido | C40: X | D40: CARLA MARTINEZ | E40: =IF(C40 ="","",C40-Listas!$B$2) -> #VALUE! | F40: 33 1893 0520 | G40: 02 DE ABRIL 2025
... A54: KAROL PEREZ | B54: Referido | C54: YA TIENE PLANES EN MONTERREY | D54: CARLA MARTINEZ | E54: =IF(C54 ="","",C54-Listas!$B$2) -> #VALUE! | F54: 33 1445 5799 | G54: 14 DE ABRIL 2025
A55: KAROL VARGAS | B55: Referido | C55: X | D55: CARLA MARTINEZ | E55: =IF(C55 ="","",C55-Listas!$B$2) -> #VALUE! | F55: 3314312352 | G55: 14 DE ABRIL 2025
A56: KEISSY RUIZ | B56: Referido | C56: X | D56: CARLA MARTINEZ | E56: =IF(C56 ="","",C56-Listas!$B$2) -> #VALUE! | F56: 33 3749 2139 | G56: 16 DE ABRIL 2025
A57: KEVIN CONEJO | B57: Referido | C57: BUSCAR EN AGOSTO 2025 | D57: CARLA MARTINEZ | E57: =IF(C57 ="","",C57-Listas!$B$2) -> #VALUE! | F57: 33 1449 7109 | G57: 02 DE MAYO 2025
...

Sheet Análisis de Info Histórico
C3: Análisis de Información Histórico
CH8: Tabla de Número de pólizas por Año
B9: Promedio de Prima anual | G9: Tabla de Número de pólizas por año | P9: Hombre vs Mujer | U9: Promedio de Prima anual Hombre vs Mujer | AC9: Tabla de Número de pólizas por año Hombre vs Mujer | AK9: Bloque de edades | AP9: Promedio de Prima anual por edades | BA9: Tabla de Número de pólizas por año por edades | BN9: Promedio de Prima anual Vida | BS9: Tabla de Número de pólizas de Vida por año | BX9: Promedio de Prima anual Gastos Médicos | CC9: Tabla de Número de pólizas de Gastos Médicos por año | CO9: Tabla de Modo de cobro | CS9: Tabla de Tipo de moneda | CW9: Tabla de Forma de pago
CH11: Mes | CI11: Número de polizas | CO11: Modo de Cobro | CP11: Cantidad de pagos | CQ11: Porcentaje | CS11: Tipo de moneda | CT11: Cantidad de pagos | CU11: Porcentaje | CW11: Forma de pago | CX11: Cantidad de pagos | CY11: Porcentaje
CH12: 2018 | CI12: =COUNTIFS('BD Asesor'!$R:$R,CH12) -> 3 | CO12: TC | CP12: =COUNTIF('BD Asesor'!$A:$L,CO12) -> 146 | CQ12: =CP12/$CP$14 -> 0.66666667 | CS12: MXN | CT12: =COUNTIF('BD Asesor'!$A:$L,CS12) -> 84 | CU12: =CT12/$CT$15 -> 0.32307692 | CW12: Mensual | CX12: =COUNTIF('BD Asesor'!$A:$L,CW12) -> 61 | CY12: =CX12/$CX$16 -> 0.23282443
CH13: 2019 | CI13: =COUNTIFS('BD Asesor'!$R:$R,CH13) -> 1 | CO13: TD | CP13: =COUNTIF('BD Asesor'!$A:$L,CO13) -> 73 | CQ13: =CP13/$CP$14 -> 0.33333333 | CS13: USD | CT13: =COUNTIF('BD Asesor'!$A:$L,CS13) -> 3 | CU13: =CT13/$CT$15 -> 0.011538462 | CW13: Trimestral | CX13: =COUNTIF('BD Asesor'!$A:$L,CW13) -> 19 | CY13: =CX13/$CX$16 -> 0.072519084
CH14: 2021 | CI14: =COUNTIFS('BD Asesor'!$R:$R,CH14) -> 45 | CO14: Total | CP14: =SUM(CP12:CP13) -> 219 | CS14: UDIS | CT14: =COUNTIF('BD Asesor'!$A:$L,CS14) -> 173 | CU14: =CT14/$CT$15 -> 0.66538462 | CW14: Semestral | CX14: =COUNTIF('BD Asesor'!$A:$L,CW14) -> 44 | CY14: =CX14/$CX$16 -> 0.16793893
CH15: 2022 | CI15: =COUNTIFS('BD Asesor'!$R:$R,CH15) -> 44 | CS15: Total | CT15: =SUM(CT12:CT14) -> 260 | CW15: Anual | CX15: =COUNTIF('BD Asesor'!$A:$L,CW15) -> 138 | CY15: =CX15/$CX$16 -> 0.52671756
CH16: 2023 | CI16: =COUNTIFS('BD Asesor'!$R:$R,CH16) -> 44 | CW16: Total | CX16: =SUM(CX12:CX15) -> 262
CH17: 2024 | CI17: =COUNTIFS('BD Asesor'!$R:$R,CH17) -> 43
CH18: 2025 | CI18: =COUNTIFS('BD Asesor'!$R:$R,CH18) -> 32 | CO18: Tabla de Tipo de plan | CS18: Tabla de Estado de Pólizas
CH19: 2026 | CI19: =COUNTIFS('BD Asesor'!$R:$R,CH19) -> 11 | CO19: Tipo de Plan | CP19: Cantidad de Tipo de plan | CQ19: Porcentaje | CS19: Estado | CT19: Cantidad de pagos | CU19: Porcentaje
CH20: 2027 | CI20: =COUNTIFS('BD Asesor'!$R:$R,CH20) -> 0 | CO20: Vida | CP20: =COUNTIF('BD Asesor'!$A:$L,CO20) -> 176 | CQ20: =CP20/$CP$22 -> 0.6743295 | CS20: Activo | CT20: =COUNTIF('BD Asesor'!$A:$L,CS20) -> 262 | CU20: =CT20/$CT$22 -> 1
CH21: 2028 | CI21: =COUNTIFS('BD Asesor'!$R:$R,CH21) -> 0 | CO21: Gastos Médicos | CP21: =COUNTIF('BD Asesor'!$A$7:$L$1008,CO21) -> 85 | CQ21: =CP21/$CP$22 -> 0.3256705 | CS21: Inactivo | CT21: =COUNTIF('BD Asesor'!$A:$L,CS21) -> 0 | CU21: =CT21/$CT$22 -> 0
CH22: 2029 | CI22: =COUNTIFS('BD Asesor'!$R:$R,CH22) -> 0 | CO22: Total | CP22: =SUM(CP20:CP21) -> 261 | CS22: Total | CT22: =SUM(CT20:CT21) -> 262
CH23: 2030 | CI23: =COUNTIFS('BD Asesor'!$R:$R,CH23) -> 0
CH24: Total | CI24: =SUM(CI12:CI23) -> 223

Sheet Análisis de Info Anual
C3: Análisis de Información Histórico
D5: Año
D6: 2023
CF8: Tabla de Número de pólizas por mes
B9: Promedio de Prima | G9: Tabla de Número de pólizas | P9: Hombre vs Mujer | U9: Promedio de Prima anual Hombre vs Mujer | AC9: Tabla de Número de pólizas por año Hombre vs Mujer | AK9: Bloque de edades | AP9: Promedio de Prima anual por edades | BA9: Tabla de Número de pólizas por año por edades | BL9: Promedio de Prima anual Vida | BQ9: Tabla de Número de pólizas de Vida por año | BV9: Promedio de Prima anual Gastos Médicos | CA9: Tabla de Número de pólizas de Gastos Médicos por año | CM9: Tabla de Modo de cobro | CQ9: Tabla de Tipo de moneda | CU9: Tabla de Forma de pago
CF11: Mes | CG11: Número de polizas | CM11: Modo de Cobro | CN11: Cantidad de pagos | CO11: Porcentaje | CQ11: Tipo de moneda | CR11: Cantidad de pagos | CS11: Porcentaje | CU11: Forma de pago | CV11: Cantidad de pagos | CW11: Porcentaje
CF12: Enero | CG12: =COUNTIFS('BD Asesor'!$Q:$Q,CF12,'BD Asesor'!$R:$R,$D$6) -> 2 | CM12: TC | CN12: =COUNTIFS('BD Asesor'!$K:$K,CM12,'BD Asesor'!$R:$R,$D$6) -> 27 | CO12: =IFERROR(CN12/$CN$14,"0.00%") -> 0.81818182 | CQ12: MXN | CR12: =COUNTIFS('BD Asesor'!$G:$G,CM12,'BD Asesor'!$R:$R,$D$6) -> 0 | CS12: =IFERROR(CN12/$CR$15,"0.00%") -> 0.00% | CU12: Mensual | CV12: =COUNTIFS('BD Asesor'!$H:$H,CU12,'BD Asesor'!$R:$R,$D$6) -> 3 | CW12: =IFERROR(CN12/$CV$16,"0.00%") -> 0.61363636
CF13: Febrero | CG13: =COUNTIFS('BD Asesor'!$Q:$Q,CF13,'BD Asesor'!$R:$R,$D$6) -> 5 | CM13: TD | CN13: =COUNTIFS('BD Asesor'!$K:$K,CM13,'BD Asesor'!$R:$R,$D$6) -> 6 | CO13: =IFERROR(CN13/$CN$14,"0.00%") -> 0.18181818 | CQ13: USD | CR13: =COUNTIFS('BD Asesor'!$G:$G,CM13,'BD Asesor'!$R:$R,$D$6) -> 0 | CS13: =IFERROR(CN13/$CR$15,"0.00%") -> 0.00% | CU13: Trimestral | CV13: =COUNTIFS('BD Asesor'!$H:$H,CU13,'BD Asesor'!$R:$R,$D$6) -> 3 | CW13: =CV13/$CV$16 -> 0.068181818
CF14: Marzo | CG14: =COUNTIFS('BD Asesor'!$Q:$Q,CF14,'BD Asesor'!$R:$R,$D$6) -> 2 | CM14: Total | CN14: =SUM(CN12:CN13) -> 33 | CQ14: UDIS | CR14: =COUNTIFS('BD Asesor'!$G:$G,CM14,'BD Asesor'!$R:$R,$D$6) -> 0 | CS14: =IFERROR(CN14/$CR$15,"0.00%") -> 0.00% | CU14: Semestral | CV14: =COUNTIFS('BD Asesor'!$H:$H,CU14,'BD Asesor'!$R:$R,$D$6) -> 5 | CW14: =CV14/$CV$16 -> 0.11363636
CF15: Abril | CG15: =COUNTIFS('BD Asesor'!$Q:$Q,CF15,'BD Asesor'!$R:$R,$D$6) -> 5 | CQ15: Total | CR15: =SUM(CR12:CR14) -> 0 | CU15: Anual | CV15: =COUNTIFS('BD Asesor'!$H:$H,CU15,'BD Asesor'!$R:$R,$D$6) -> 33 | CW15: =CV15/$CV$16 -> 0.75
CF16: Mayo | CG16: =COUNTIFS('BD Asesor'!$Q:$Q,CF16,'BD Asesor'!$R:$R,$D$6) -> 3 | CU16: Total | CV16: =SUM(CV12:CV15) -> 44
CF17: Junio | CG17: =COUNTIFS('BD Asesor'!$Q:$Q,CF17,'BD Asesor'!$R:$R,$D$6) -> 2
CF18: Julio | CG18: =COUNTIFS('BD Asesor'!$Q:$Q,CF18,'BD Asesor'!$R:$R,$D$6) -> 4 | CM18: Tabla de Tipo de plan | CQ18: Tabla de Estado de Pólizas
CF19: Agosto | CG19: =COUNTIFS('BD Asesor'!$Q:$Q,CF19,'BD Asesor'!$R:$R,$D$6) -> 6 | CM19: Tipo de Plan | CN19: Cantidad de Tipo de plan | CO19: Porcentaje | CQ19: Estado | CR19: Cantidad de pagos | CS19: Porcentaje
CF20: Septiembre | CG20: =COUNTIFS('BD Asesor'!$Q:$Q,CF20,'BD Asesor'!$R:$R,$D$6) -> 3 | CM20: Vida | CN20: =COUNTIFS('BD Asesor'!$L:$L,CM20,'BD Asesor'!$R:$R,$D$6) -> 20 | CO20: =CN20/$CN$22 -> 0.46511628 | CQ20: Activo | CR20: =COUNTIFS('BD Asesor'!$C:$C,CQ20,'BD Asesor'!$R:$R,$D$6) -> 44 | CS20: =IFERROR(CN12/$CR$22,"0.00%") -> 0.61363636
CF21: Octubre | CG21: =COUNTIFS('BD Asesor'!$Q:$Q,CF21,'BD Asesor'!$R:$R,$D$6) -> 2 | CM21: Gastos Médicos | CN21: =COUNTIFS('BD Asesor'!$L:$L,CM21,'BD Asesor'!$R:$R,$D$6) -> 23 | CO21: =CN21/$CN$22 -> 0.53488372 | CQ21: Inactivo | CR21: =COUNTIFS('BD Asesor'!$C:$C,CQ21,'BD Asesor'!$R:$R,$D$6) -> 0 | CS21: =IFERROR(CN13/$CR$22,"0.00%") -> 0.13636364
CF22: Noviembre | CG22: =COUNTIFS('BD Asesor'!$Q:$Q,CF22,'BD Asesor'!$R:$R,$D$6) -> 7 | CM22: Total | CN22: =SUM(CN20:CN21) -> 43 | CQ22: Total | CR22: =SUM(CR20:CR21) -> 44
CF23: Diciembre | CG23: =COUNTIFS('BD Asesor'!$Q:$Q,CF23,'BD Asesor'!$R:$R,$D$6) -> 3
CF24: Total | CG24: =SUM(CG12:CG23) -> 44

Sheet Listas
A2: Hoy | B2: =TODAY() -> 46161 | C2: 1 | D2: Enero | F2: Vida | G2: Gastos Médicos
A3: =DAY(B2) -> 19 | B3: =MONTH(B2) -> 5 | C3: 2 | D3: Febrero
C4: 3 | D4: Marzo | F4: Orvi | G4: Pleno | I4: =IFERROR(__xludf.DUMMYFUNCTION("FILTER('BD Asesor'!A8:A1998,'BD Asesor'!C8:C1998=""Activo"")"),"ABRAHAM GALICIA MANCERA") -> ABRAHAM GALICIA MANCERA
C5: 4 | D5: Abril | F5: Dotal | G5: Integro | I5: =IFERROR(__xludf.DUMMYFUNCTION("""COMPUTED_VALUE"""),"ABRAHAM GALICIA MANCERA") -> ABRAHAM GALICIA MANCERA
C6: 5 | D6: Mayo | F6: Vida mujer | G6: Practico | I6: =IFERROR(__xludf.DUMMYFUNCTION("""COMPUTED_VALUE"""),"ADRIAN ALEJANDRO RAMIREZ MORALES") -> ADRIAN ALEJANDRO RAMIREZ MORALES
B7: 2018 | C7: 6 | D7: Junio | F7: Imagina ser | G7: Flex A | I7: =IFERROR(__xludf.DUMMYFUNCTION("""COMPUTED_VALUE"""),"ADRIAN ALEJANDRO RAMIREZ MORALES") -> ADRIAN ALEJANDRO RAMIREZ MORALES
B8: 2019 | C8: 7 | D8: Julio | F8: Nuevo planitud | G8: Flex B | I8: =IFERROR(__xludf.DUMMYFUNCTION("""COMPUTED_VALUE"""),"AIDA GRACIELA FLORES BARBA") -> AIDA GRACIELA FLORES BARBA
B9: 2020 | C9: 8 | D9: Agosto | F9: Segubeca | I9: =IFERROR(__xludf.DUMMYFUNCTION("""COMPUTED_VALUE"""),"ALEJANDRA DEL CARMEN UREÑA CASILLAS") -> ALEJANDRA DEL CARMEN UREÑA CASILLAS
B10: 2021 | C10: 9 | D10: Septiembre | F10: Mio | I10: =IFERROR(__xludf.DUMMYFUNCTION("""COMPUTED_VALUE"""),"ALEJANDRA DEL CARMEN UREÑA CASILLAS") -> ALEJANDRA DEL CARMEN UREÑA CASILLAS
B11: 2022 | C11: 10 | D11: Octubre | I11: =IFERROR(__xludf.DUMMYFUNCTION("""COMPUTED_VALUE"""),"ALEJANDRA DEL CARMEN UREÑA CASILLAS") -> ALEJANDRA DEL CARMEN UREÑA CASILLAS
B12: 2023 | C12: 11 | D12: Noviembre | I12: =IFERROR(__xludf.DUMMYFUNCTION("""COMPUTED_VALUE"""),"ALEJANDRO ARTURO LOMELI OROZCO") -> ALEJANDRO ARTURO LOMELI OROZCO
B13: 2024 | C13: 12 | D13: Diciembre | I13: =IFERROR(__xludf.DUMMYFUNCTION("""COMPUTED_VALUE"""),"ALEJANDRO MORENO TRUJILLO") -> ALEJANDRO MORENO TRUJILLO
B14: 2025 | I14: =IFERROR(__xludf.DUMMYFUNCTION("""COMPUTED_VALUE"""),"ALEJANDRO MORENO TRUJILLO") -> ALEJANDRO MORENO TRUJILLO
B15: 2026 | I15: =IFERROR(__xludf.DUMMYFUNCTION("""COMPUTED_VALUE"""),"ALEJANDRO SOTO ELIZALDE") -> ALEJANDRO SOTO ELIZALDE
I16: =IFERROR(__xludf.DUMMYFUNCTION("""COMPUTED_VALUE"""),"ALEJANDRO VAZQUEZ RODRIGUEZ") -> ALEJANDRO VAZQUEZ RODRIGUEZ
I17: =IFERROR(__xludf.DUMMYFUNCTION("""COMPUTED_VALUE"""),"ALEXA GISELLE INFANTE JAIME") -> ALEXA GISELLE INFANTE JAIME
I18: =IFERROR(__xludf.DUMMYFUNCTION("""COMPUTED_VALUE"""),"ANA KAREN MUÑIZ CHAVEZ") -> ANA KAREN MUÑIZ CHAVEZ
I19: =IFERROR(__xludf.DUMMYFUNCTION("""COMPUTED_VALUE"""),"ANA PAULA GONZALEZ LUNA NIÑO") -> ANA PAULA GONZALEZ LUNA NIÑO
I20: =IFERROR(__xludf.DUMMYFUNCTION("""COMPUTED_VALUE"""),"ANDREA HERNANDEZ MERCADO") -> ANDREA HERNANDEZ MERCADO
I21: =IFERROR(__xludf.DUMMYFUNCTION("""COMPUTED_VALUE"""),"ANGELICA ALEJANDRA SANCHEZ DURAN") -> ANGELICA ALEJANDRA SANCHEZ DURAN
I22: =IFERROR(__xludf.DUMMYFUNCTION("""COMPUTED_VALUE"""),"ARNOLD SANCHEZ SANCHEZ") -> ARNOLD SANCHEZ SANCHEZ
I23: =IFERROR(__xludf.DUMMYFUNCTION("""COMPUTED_VALUE"""),"BERNARDO GARCIA GOMEZ") -> BERNARDO GARCIA GOMEZ
I24: =IFERROR(__xludf.DUMMYFUNCTION("""COMPUTED_VALUE"""),"BERNARDO GARCIA GOMEZ") -> BERNARDO GARCIA GOMEZ
I25: =IFERROR(__xludf.DUMMYFUNCTION("""COMPUTED_VALUE"""),"BETH SUA MONTEJANO CARMONA") -> BETH SUA MONTEJANO CARMONA
I26: =IFERROR(__xludf.DUMMYFUNCTION("""COMPUTED_VALUE"""),"BLANCA CAROLINA MAGAÑA CASTELLON") -> BLANCA CAROLINA MAGAÑA CASTELLON
I27: =IFERROR(__xludf.DUMMYFUNCTION("""COMPUTED_VALUE"""),"CARLA ANDREA MARTINEZ LAGOS") -> CARLA ANDREA MARTINEZ LAGOS
I28: =IFERROR(__xludf.DUMMYFUNCTION("""COMPUTED_VALUE"""),"CARLOS ALBERTO MORALES NOGUEDA") -> CARLOS ALBERTO MORALES NOGUEDA
I29: =IFERROR(__xludf.DUMMYFUNCTION("""COMPUTED_VALUE"""),"CARLOS CASTRO PALAZUELOS") -> CARLOS CASTRO PALAZUELOS
I30: =IFERROR(__xludf.DUMMYFUNCTION("""COMPUTED_VALUE"""),"CARLOS DAVID AVILA URRUCHUA") -> CARLOS DAVID AVILA URRUCHUA
I31: =IFERROR(__xludf.DUMMYFUNCTION("""COMPUTED_VALUE"""),"CARLOS HUMBERTO VILLANUEVA CARMONA") -> CARLOS HUMBERTO VILLANUEVA CARMONA
I32: =IFERROR(__xludf.DUMMYFUNCTION("""COMPUTED_VALUE"""),"CARLOS VERDUZO FAVELA") -> CARLOS VERDUZO FAVELA
I33: =IFERROR(__xludf.DUMMYFUNCTION("""COMPUTED_VALUE"""),"CARLOS XAVIER BARBA LOPEZ") -> CARLOS XAVIER BARBA LOPEZ
I34: =IFERROR(__xludf.DUMMYFUNCTION("""COMPUTED_VALUE"""),"CECILIA ARCEO CERVANTES") -> CECILIA ARCEO CERVANTES
I35: =IFERROR(__xludf.DUMMYFUNCTION("""COMPUTED_VALUE"""),"CESAR ISRRAEL HERNANDEZ SANCHEZ") -> CESAR ISRRAEL HERNANDEZ SANCHEZ
I36: =IFERROR(__xludf.DUMMYFUNCTION("""COMPUTED_VALUE"""),"CESAR ISRRAEL HERNANDEZ SANCHEZ") -> CESAR ISRRAEL HERNANDEZ SANCHEZ
I37: =IFERROR(__xludf.DUMMYFUNCTION("""COMPUTED_VALUE"""),"CINTHIA NOEMI JASSO TORRES") -> CINTHIA NOEMI JASSO TORRES
I38: =IFERROR(__xludf.DUMMYFUNCTION("""COMPUTED_VALUE"""),"CLAUDIO ALBERTO MARTIN LOPEZ") -> CLAUDIO ALBERTO MARTIN LOPEZ
I39: =IFERROR(__xludf.DUMMYFUNCTION("""COMPUTED_VALUE"""),"CRISTINA GUADALUPE ALVAREZ HERNANDEZ") -> CRISTINA GUADALUPE ALVAREZ HERNANDEZ
I40: =IFERROR(__xludf.DUMMYFUNCTION("""COMPUTED_VALUE"""),"CRISTINA LETICIA RODRIGUEZ DE LA TORRE") -> CRISTINA LETICIA RODRIGUEZ DE LA TORRE
I41: =IFERROR(__xludf.DUMMYFUNCTION("""COMPUTED_VALUE"""),"CYNTHIA ELIZABETH MORALES ORTEGA") -> CYNTHIA ELIZABETH MORALES ORTEGA
...

Sheet Mina de Oro
A2: Mes: | B2: Junio
C5: Cliente | D5: Sexo | E5: Estado | F5: Emisión | G5: Número de póliza | H5: Prima anual | I5: Tipo de plan | J5: Nombre del plan
C6: =IFERROR(__xludf.DUMMYFUNCTION("FILTER('BD Asesor'!A8:F1000,'BD Asesor'!Q8:Q1000=B2,'BD Asesor'!C8:C1000=""Activo"")"),"ALEJANDRA DEL CARMEN UREÑA CASILLAS") -> ALEJANDRA DEL CARMEN UREÑA CASILLAS | D6: =IFERROR(__xludf.DUMMYFUNCTION("""COMPUTED_VALUE"""),"M") -> M | E6: =IFERROR(__xludf.DUMMYFUNCTION("""COMPUTED_VALUE"""),"Activo") -> Activo | F6: =IFERROR(__xludf.DUMMYFUNCTION("""COMPUTED_VALUE"""),44008.0) -> 44008 | G6: =IFERROR(__xludf.DUMMYFUNCTION("""COMPUTED_VALUE"""),"GM0000478411") -> GM0000478411 | H6: =IFERROR(__xludf.DUMMYFUNCTION("""COMPUTED_VALUE"""),10660.33) -> 10660.33 | I6: =IFERROR(__xludf.DUMMYFUNCTION("FILTER('BD Asesor'!L8:M1000,'BD Asesor'!Q8:Q1000=B2,'BD Asesor'!C8:C1000=""Activo"")"),"Gastos Médicos ") -> Gastos Médicos | J6: =IFERROR(__xludf.DUMMYFUNCTION("""COMPUTED_VALUE"""),"Integro") -> Integro
C7: =IFERROR(__xludf.DUMMYFUNCTION("""COMPUTED_VALUE"""),"CESAR ISRRAEL HERNANDEZ SANCHEZ") -> CESAR ISRRAEL HERNANDEZ SANCHEZ | D7: =IFERROR(__xludf.DUMMYFUNCTION("""COMPUTED_VALUE"""),"H") -> H | E7: =IFERROR(__xludf.DUMMYFUNCTION("""COMPUTED_VALUE"""),"Activo") -> Activo | F7: =IFERROR(__xludf.DUMMYFUNCTION("""COMPUTED_VALUE"""),44728.0) -> 44728 | G7: =IFERROR(__xludf.DUMMYFUNCTION("""COMPUTED_VALUE"""),"VI0002672529") -> VI0002672529 | H7: =IFERROR(__xludf.DUMMYFUNCTION("""COMPUTED_VALUE"""),94684.68359999999) -> 94684.684 | I7: =IFERROR(__xludf.DUMMYFUNCTION("""COMPUTED_VALUE"""),"Vida") -> Vida | J7: =IFERROR(__xludf.DUMMYFUNCTION("""COMPUTED_VALUE"""),"Orvi") -> Orvi
C8: =IFERROR(__xludf.DUMMYFUNCTION("""COMPUTED_VALUE"""),"FRANCISCO JAVIER VALENCIA PRADO") -> FRANCISCO JAVIER VALENCIA PRADO | D8: =IFERROR(__xludf.DUMMYFUNCTION("""COMPUTED_VALUE"""),"H") -> H | E8: =IFERROR(__xludf.DUMMYFUNCTION("""COMPUTED_VALUE"""),"Activo") -> Activo | F8: =IFERROR(__xludf.DUMMYFUNCTION("""COMPUTED_VALUE"""),44012.0) -> 44012 | G8: =IFERROR(__xludf.DUMMYFUNCTION("""COMPUTED_VALUE"""),"GM0000479419") -> GM0000479419 | H8: =IFERROR(__xludf.DUMMYFUNCTION("""COMPUTED_VALUE"""),16188.72) -> 16188.72 | I8: =IFERROR(__xludf.DUMMYFUNCTION("""COMPUTED_VALUE"""),"Gastos Médicos ") -> Gastos Médicos | J8: =IFERROR(__xludf.DUMMYFUNCTION("""COMPUTED_VALUE"""),"Integro") -> Integro
C9: =IFERROR(__xludf.DUMMYFUNCTION("""COMPUTED_VALUE"""),"GUSTAVO GUTIERREZ PLASCENCIA") -> GUSTAVO GUTIERREZ PLASCENCIA | D9: =IFERROR(__xludf.DUMMYFUNCTION("""COMPUTED_VALUE"""),"H") -> H | E9: =IFERROR(__xludf.DUMMYFUNCTION("""COMPUTED_VALUE"""),"Activo") -> Activo | F9: =IFERROR(__xludf.DUMMYFUNCTION("""COMPUTED_VALUE"""),44362.0) -> 44362 | G9: =IFERROR(__xludf.DUMMYFUNCTION("""COMPUTED_VALUE"""),"VI0002607534") -> VI0002607534 | H9: =IFERROR(__xludf.DUMMYFUNCTION("""COMPUTED_VALUE"""),23822.451220000003) -> 23822.451 | I9: =IFERROR(__xludf.DUMMYFUNCTION("""COMPUTED_VALUE"""),"Vida") -> Vida | J9: =IFERROR(__xludf.DUMMYFUNCTION("""COMPUTED_VALUE"""),"Orvi") -> Orvi
C10: =IFERROR(__xludf.DUMMYFUNCTION("""COMPUTED_VALUE"""),"IZCHEL IRAIS GONZALEZ DIAZ") -> IZCHEL IRAIS GONZALEZ DIAZ | D10: =IFERROR(__xludf.DUMMYFUNCTION("""COMPUTED_VALUE"""),"M") -> M | E10: =IFERROR(__xludf.DUMMYFUNCTION("""COMPUTED_VALUE"""),"Activo") -> Activo | F10: =IFERROR(__xludf.DUMMYFUNCTION("""COMPUTED_VALUE"""),44366.0) -> 44366 | G10: =IFERROR(__xludf.DUMMYFUNCTION("""COMPUTED_VALUE"""),"VI0002608269") -> VI0002608269 | H10: =IFERROR(__xludf.DUMMYFUNCTION("""COMPUTED_VALUE"""),17576.90448) -> 17576.904 | I10: =IFERROR(__xludf.DUMMYFUNCTION("""COMPUTED_VALUE"""),"Vida") -> Vida | J10: =IFERROR(__xludf.DUMMYFUNCTION("""COMPUTED_VALUE"""),"Orvi") -> Orvi
C11: =IFERROR(__xludf.DUMMYFUNCTION("""COMPUTED_VALUE"""),"JAZMIN JUDITH HERNANDEZ AGUIRRE") -> JAZMIN JUDITH HERNANDEZ AGUIRRE | D11: =IFERROR(__xludf.DUMMYFUNCTION("""COMPUTED_VALUE"""),"M") -> M | E11: =IFERROR(__xludf.DUMMYFUNCTION("""COMPUTED_VALUE"""),"Activo") -> Activo | F11: =IFERROR(__xludf.DUMMYFUNCTION("""COMPUTED_VALUE"""),44740.0) -> 44740 | G11: =IFERROR(__xludf.DUMMYFUNCTION("""COMPUTED_VALUE"""),"VI0002675317") -> VI0002675317 | H11: =IFERROR(__xludf.DUMMYFUNCTION("""COMPUTED_VALUE"""),16748.0079) -> 16748.008 | I11: =IFERROR(__xludf.DUMMYFUNCTION("""COMPUTED_VALUE"""),"Vida") -> Vida | J11: =IFERROR(__xludf.DUMMYFUNCTION("""COMPUTED_VALUE"""),"Segubeca") -> Segubeca
C12: =IFERROR(__xludf.DUMMYFUNCTION("""COMPUTED_VALUE"""),"OSCAR ARTURO CORREA SOTO") -> OSCAR ARTURO CORREA SOTO | D12: =IFERROR(__xludf.DUMMYFUNCTION("""COMPUTED_VALUE"""),"H") -> H | E12: =IFERROR(__xludf.DUMMYFUNCTION("""COMPUTED_VALUE"""),"Activo") -> Activo | F12: =IFERROR(__xludf.DUMMYFUNCTION("""COMPUTED_VALUE"""),44372.0) -> 44372 | G12: =IFERROR(__xludf.DUMMYFUNCTION("""COMPUTED_VALUE"""),"VI0002610198") -> VI0002610198 | H12: =IFERROR(__xludf.DUMMYFUNCTION("""COMPUTED_VALUE"""),38433.71218) -> 38433.712 | I12: =IFERROR(__xludf.DUMMYFUNCTION("""COMPUTED_VALUE"""),"Vida") -> Vida | J12: =IFERROR(__xludf.DUMMYFUNCTION("""COMPUTED_VALUE"""),"Orvi") -> Orvi
C13: =IFERROR(__xludf.DUMMYFUNCTION("""COMPUTED_VALUE"""),"PAOLA RAMOS REYNOSO") -> PAOLA RAMOS REYNOSO | D13: =IFERROR(__xludf.DUMMYFUNCTION("""COMPUTED_VALUE"""),"M") -> M | E13: =IFERROR(__xludf.DUMMYFUNCTION("""COMPUTED_VALUE"""),"Activo") -> Activo | F13: =IFERROR(__xludf.DUMMYFUNCTION("""COMPUTED_VALUE"""),44357.0) -> 44357 | G13: =IFERROR(__xludf.DUMMYFUNCTION("""COMPUTED_VALUE"""),"VI0002606703") -> VI0002606703 | H13: =IFERROR(__xludf.DUMMYFUNCTION("""COMPUTED_VALUE"""),31557.93772) -> 31557.938 | I13: =IFERROR(__xludf.DUMMYFUNCTION("""COMPUTED_VALUE"""),"Vida") -> Vida | J13: =IFERROR(__xludf.DUMMYFUNCTION("""COMPUTED_VALUE"""),"Orvi") -> Orvi
